<?xml version="1.0" ?>
<!-- =================================================================================== -->
<!-- |    This document was autogenerated by xacro from gen3_robotiq_2f_85.xacro       | -->
<!-- |    EDITING THIS FILE BY HAND IS NOT RECOMMENDED                                 | -->
<!-- =================================================================================== -->
<robot name="gen3">
    <!-- Run the macros -->
    <link name="base_link">
        <inertial>
            <origin rpy="0 0 0" xyz="-0.000648 -0.000166 0.084487" />
            <mass value="1.697" />
            <inertia ixx="0.004622" ixy="9E-06" ixz="6E-05" iyy="0.004495" iyz="9E-06" izz="0.002079" />
        </inertial>
        <visual>
            <origin rpy="0 0 0" xyz="0 0 0" />
            <geometry>
                <mesh filename="meshes/base_link.stl" />
            </geometry>
            <material name="">
                <color rgba="0.75294 0.75294 0.75294 1" />
            </material>
        </visual>
        <collision>
            <origin rpy="0 0 0" xyz="0 0 0" />
            <geometry>
                <mesh filename="meshes/base_link.stl" />
            </geometry>
        </collision>
    </link>
    <link name="shoulder_link">
        <inertial>
            <origin rpy="0 0 0" xyz="-2.3E-05 -0.010364 -0.07336" />
            <mass value="1.3773" />
            <inertia ixx="0.00457" ixy="1E-06" ixz="2E-06" iyy="0.004831" iyz="0.000448" izz="0.001409" />
        </inertial>
        <visual>
            <origin rpy="0 0 0" xyz="0 0 0" />
            <geometry>
                <mesh filename="meshes/shoulder_link.stl" />
            </geometry>
            <material name="">
                <color rgba="0.75294 0.75294 0.75294 1" />
            </material>
        </visual>
        <collision>
            <origin rpy="0 0 0" xyz="0 0 0" />
            <geometry>
                <mesh filename="meshes/shoulder_link.stl" />
            </geometry>
        </collision>
    </link>
    <joint name="joint_1" type="revolute">
        <origin rpy="3.1416 2.7629E-18 -4.9305E-36" xyz="0 0 0.15643" />
        <parent link="base_link" />
        <child link="shoulder_link" />
        <axis xyz="0 0 1" />
        <limit effort="39" velocity="1.3963" />
        <dynamics friction="0.5217383101288284" damping="10.5" lower="-10.0" upper="10.0"/>
    </joint>
    <link name="half_arm_1_link">
        <inertial>
            <origin rpy="0 0 0" xyz="-4.4E-05 -0.09958 -0.013278" />
            <mass value="1.1636" />
            <inertia ixx="0.011088" ixy="5E-06" ixz="0" iyy="0.001072" iyz="-0.000691" izz="0.011255" />
        </inertial>
        <visual>
            <origin rpy="0 0 0" xyz="0 0 0" />
            <geometry>
                <mesh filename="meshes/half_arm_1_link.stl" />
            </geometry>
            <material name="">
                <color rgba="0.75294 0.75294 0.75294 1" />
            </material>
        </visual>
        <collision>
            <origin rpy="0 0 0" xyz="0 0 0" />
            <geometry>
                <mesh filename="meshes/half_arm_1_link.stl" />
            </geometry>
        </collision>
    </link>
    <joint name="joint_2" type="revolute">
        <origin rpy="1.5708 2.1343E-17 -1.1102E-16" xyz="0 0.005375 -0.12838" />
        <parent link="shoulder_link" />
        <child link="half_arm_1_link" />
        <axis xyz="0 0 1" />
        <limit effort="39" lower="-2.41" upper="2.41" velocity="1.3963" />
        <dynamics friction="0.5769579059927288" damping="7.406484581723072" />
    </joint>
    <link name="half_arm_2_link">
        <inertial>
            <origin rpy="0 0 0" xyz="-4.4E-05 -0.006641 -0.117892" />
            <mass value="1.1636" />
            <inertia ixx="0.010932" ixy="0" ixz="-7E-06" iyy="0.011127" iyz="0.000606" izz="0.001043" />
        </inertial>
        <visual>
            <origin rpy="0 0 0" xyz="0 0 0" />
            <geometry>
                <mesh filename="meshes/half_arm_2_link.stl" />
            </geometry>
            <material name="">
                <color rgba="0.75294 0.75294 0.75294 1" />
            </material>
        </visual>
        <collision>
            <origin rpy="0 0 0" xyz="0 0 0" />
            <geometry>
                <mesh filename="meshes/half_arm_2_link.stl" />
            </geometry>
        </collision>
    </link>
    <joint name="joint_3" type="revolute">
        <origin rpy="-1.5708 1.2326E-32 -2.9122E-16" xyz="0 -0.21038 -0.006375" />
        <parent link="half_arm_1_link" />
        <child link="half_arm_2_link" />
        <axis xyz="0 0 1" />
        <limit effort="39" velocity="1.3963" />
        <dynamics friction="0.4213397946418778" damping="9.972763340817286" lower="-10.0" upper="10.0"/>
    </joint>
    <link name="forearm_link">
        <inertial>
            <origin rpy="0 0 0" xyz="-1.8E-05 -0.075478 -0.015006" />
            <mass value="0.9302" />
            <inertia ixx="0.008147" ixy="-1E-06" ixz="0" iyy="0.000631" iyz="-0.0005" izz="0.008316" />
        </inertial>
        <visual>
            <origin rpy="0 0 0" xyz="0 0 0" />
            <geometry>
                <mesh filename="meshes/forearm_link.stl" />
            </geometry>
            <material name="">
                <color rgba="0.75294 0.75294 0.75294 1" />
            </material>
        </visual>
        <collision>
            <origin rpy="0 0 0" xyz="0 0 0" />
            <geometry>
                <mesh filename="meshes/forearm_link.stl" />
            </geometry>
        </collision>
    </link>
    <joint name="joint_4" type="revolute">
        <origin rpy="1.5708 -6.6954E-17 -1.6653E-16" xyz="0 0.006375 -0.21038" />
        <parent link="half_arm_2_link" />
        <child link="forearm_link" />
        <axis xyz="0 0 1" />
        <limit effort="39" lower="-2.66" upper="2.66" velocity="1.3963" />
        <dynamics friction="0.4945515376566732" damping="8.266795082250392" lower="-10.0" upper="10.0"/>
    </joint>
    <link name="spherical_wrist_1_link">
        <inertial>
            <origin rpy="0 0 0" xyz="1E-06 -0.009432 -0.063883" />
            <mass value="0.6781" />
            <inertia ixx="0.001596" ixy="0" ixz="0" iyy="0.001607" iyz="0.000256" izz="0.000399" />
        </inertial>
        <visual>
            <origin rpy="0 0 0" xyz="0 0 0" />
            <geometry>
                <mesh filename="meshes/spherical_wrist_1_link.stl" />
            </geometry>
            <material name="">
                <color rgba="0.75294 0.75294 0.75294 1" />
            </material>
        </visual>
        <collision>
            <origin rpy="0 0 0" xyz="0 0 0" />
            <geometry>
                <mesh filename="meshes/spherical_wrist_1_link.stl" />
            </geometry>
        </collision>
    </link>
    <joint name="joint_5" type="revolute">
        <origin rpy="-1.5708 2.2204E-16 -6.373E-17" xyz="0 -0.20843 -0.006375" />
        <parent link="forearm_link" />
        <child link="spherical_wrist_1_link" />
        <axis xyz="0 0 1" />
        <limit effort="9" velocity="1.2218" />
        <dynamics friction="0.16110705026613545" damping="8.857224902652815" />
    </joint>
    <link name="spherical_wrist_2_link">
        <inertial>
            <origin rpy="0 0 0" xyz="1E-06 -0.045483 -0.00965" />
            <mass value="0.6781" />
            <inertia ixx="0.001641" ixy="0" ixz="0" iyy="0.00041" iyz="-0.000278" izz="0.001641" />
        </inertial>
        <visual>
            <origin rpy="0 0 0" xyz="0 0 0" />
            <geometry>
                <mesh filename="meshes/spherical_wrist_2_link.stl" />
            </geometry>
            <material name="">
                <color rgba="0.75294 0.75294 0.75294 1" />
            </material>
        </visual>
        <collision>
            <origin rpy="0 0 0" xyz="0 0 0" />
            <geometry>
                <mesh filename="meshes/spherical_wrist_2_link.stl" />
            </geometry>
        </collision>
    </link>
    <joint name="joint_6" type="revolute">
        <origin rpy="1.5708 9.2076E-28 -8.2157E-15" xyz="0 0.00017505 -0.10593" />
        <parent link="spherical_wrist_1_link" />
        <child link="spherical_wrist_2_link" />
        <axis xyz="0 0 1" />
        <limit effort="9" lower="-2.23" upper="2.23" velocity="1.2218" />
        <dynamics friction="0.13334911855141302" damping="8.711083156933284" lower="-10.0" upper="10.0"/>
    </joint>
    <link name="Bracelet_Link">
        <inertial>
            <!-- This is different from the documentation -->
            <origin rpy="0 0 0" xyz="0.000281 0.011402 -0.029798" />
            <mass value="0.5" />
            <inertia ixx="0.000587" ixy="3E-06" ixz="3E-06" iyy="0.000369" iyz="-0.000118" izz="0.000609" />
        </inertial>
        <visual>
            <origin rpy="0 0 0" xyz="0 0 0" />
            <geometry>
                <mesh filename="meshes/bracelet_with_vision_link.stl" />
            </geometry>
            <material name="">
                <color rgba="0.75294 0.75294 0.75294 1" />
            </material>
        </visual>
        <collision>
            <origin rpy="0 0 0" xyz="0 0 0" />
            <geometry>
                <mesh filename="meshes/bracelet_with_vision_link.stl" />
            </geometry>
        </collision>
    </link>
    <joint name="joint_7" type="revolute">
        <origin rpy="-1.5708 -5.5511E-17 9.6396E-17" xyz="0 -0.10593 -0.00017505" />
        <parent link="spherical_wrist_2_link" />
        <child link="Bracelet_Link" />
        <axis xyz="0 0 1" />
        <limit effort="9" velocity="1.2218" />
        <dynamics friction="0.143444018171737" damping="8.888190363830693" />
    </joint>
    <!-- <link name="end_effector_link"/>
  <joint name="end_effector" type="fixed">
    <origin rpy="3.14159265358979 1.09937075168372E-32 0" xyz="0 0 -0.0615250000000001"/>
    <parent link="bracelet_link"/>
    <child link="end_effector_link"/>
    <axis xyz="0 0 0"/>
  </joint>
  <link name="camera_link"/>
  <joint name="camera_module" type="fixed">
    <origin rpy="3.14159265358979 3.14159265358979 0" xyz="0 0.05639 -0.00305"/>
    <parent link="end_effector_link"/>
    <child link="camera_link"/>
  </joint>
  <link name="camera_depth_frame"/>
  <joint name="depth_module" type="fixed">
    <origin rpy="3.14159265358979 3.14159265358979 0" xyz="0.0275 0.066 -0.00305"/>
    <parent link="end_effector_link"/>
    <child link="camera_depth_frame"/>
  </joint>
  <link name="camera_color_frame"/>
  <joint name="color_module" type="fixed">
    <origin rpy="3.14159265358979 3.14159265358979 0" xyz="0 0.05639 -0.00305"/>
    <parent link="end_effector_link"/>
    <child link="camera_color_frame"/>
  </joint> -->
    <!-- This line was removed by Kinova because we replaced the transmission file with our own
    <xacro:include filename="$(find robotiq_2f_85_gripper_visualization)/urdf/robotiq_arg2f_transmission.xacro" /> -->
    <!-- Tool frame used by the arm -->
    <!-- <link name="tool_frame"/>
  <joint name="tool_frame_joint" type="fixed">
    <origin rpy="0 0 0" xyz="0 0 0.120"/>
    <parent link="end_effector_link"/>
    <child link="tool_frame"/>
    <axis xyz="0 0 0"/>
  </joint> -->
    <!-- Transmissions are loaded in the generic kortex xacro when simulation is enabled -->
    <!-- <xacro:robotiq_arg2f_transmission prefix="${prefix}"/> -->
    <!-- Armatures NOTE: self defined convention for motorInertia -->
    <transmission name="joint_1_trans" type="transmission_interface/SimpleTransmission">
        <joint name="joint_1" />
        <actuator name="joint_1_motor" />
        <motorInertia>8.03</motorInertia>
    </transmission>
    <transmission name="joint_2_trans" type="transmission_interface/SimpleTransmission">
        <joint name="joint_2" />
        <actuator name="joint_2_motor" />
        <motorInertia>11.996202461530364</motorInertia>
    </transmission>
    <transmission name="joint_3_trans" type="transmission_interface/SimpleTransmission">
        <joint name="joint_3" />
        <actuator name="joint_3_motor" />
        <motorInertia>9.002542786175152</motorInertia>
    </transmission>
    <transmission name="joint_4_trans" type="transmission_interface/SimpleTransmission">
        <joint name="joint_4" />
        <actuator name="joint_4_motor" />
        <motorInertia>11.580643931670636</motorInertia>
    </transmission>
    <transmission name="joint_5_trans" type="transmission_interface/SimpleTransmission">
        <joint name="joint_5" />
        <actuator name="joint_5_motor" />
        <motorInertia>8.466504091791412</motorInertia>
    </transmission>
    <transmission name="joint_6_trans" type="transmission_interface/SimpleTransmission">
        <joint name="joint_6" />
        <actuator name="joint_6_motor" />
        <motorInertia>8.853706937374243</motorInertia>
    </transmission>
    <transmission name="joint_7_trans" type="transmission_interface/SimpleTransmission">
        <joint name="joint_7" />
        <actuator name="joint_7_motor" />
        <motorInertia>8.858730366468532</motorInertia>
    </transmission>
    <transmission name="trans_joint_1">
        <type>transmission_interface/SimpleTransmission</type>
        <joint name="joint_1">
            <hardwareInterface>hardware_interface/EffortJointInterface</hardwareInterface>
        </joint>
        <actuator name="joint_1_motor">
            <hardwareInterface>hardware_interface/EffortJointInterface</hardwareInterface>
            <mechanicalReduction>1</mechanicalReduction>
        </actuator>
    </transmission>
    <transmission name="trans_joint_2">
        <type>transmission_interface/SimpleTransmission</type>
        <joint name="joint_2">
            <hardwareInterface>hardware_interface/EffortJointInterface</hardwareInterface>
        </joint>
        <actuator name="joint_2_motor">
            <hardwareInterface>hardware_interface/EffortJointInterface</hardwareInterface>
            <mechanicalReduction>1</mechanicalReduction>
        </actuator>
    </transmission>
    <transmission name="trans_joint_3">
        <type>transmission_interface/SimpleTransmission</type>
        <joint name="joint_3">
            <hardwareInterface>hardware_interface/EffortJointInterface</hardwareInterface>
        </joint>
        <actuator name="joint_3_motor">
            <hardwareInterface>hardware_interface/EffortJointInterface</hardwareInterface>
            <mechanicalReduction>1</mechanicalReduction>
        </actuator>
    </transmission>
    <transmission name="trans_joint_4">
        <type>transmission_interface/SimpleTransmission</type>
        <joint name="joint_4">
            <hardwareInterface>hardware_interface/EffortJointInterface</hardwareInterface>
        </joint>
        <actuator name="joint_4_motor">
            <hardwareInterface>hardware_interface/EffortJointInterface</hardwareInterface>
            <mechanicalReduction>1</mechanicalReduction>
        </actuator>
    </transmission>
    <transmission name="trans_joint_5">
        <type>transmission_interface/SimpleTransmission</type>
        <joint name="joint_5">
            <hardwareInterface>hardware_interface/EffortJointInterface</hardwareInterface>
        </joint>
        <actuator name="joint_5_motor">
            <hardwareInterface>hardware_interface/EffortJointInterface</hardwareInterface>
            <mechanicalReduction>1</mechanicalReduction>
        </actuator>
    </transmission>
    <transmission name="trans_joint_6">
        <type>transmission_interface/SimpleTransmission</type>
        <joint name="joint_6">
            <hardwareInterface>hardware_interface/EffortJointInterface</hardwareInterface>
        </joint>
        <actuator name="joint_6_motor">
            <hardwareInterface>hardware_interface/EffortJointInterface</hardwareInterface>
            <mechanicalReduction>1</mechanicalReduction>
        </actuator>
    </transmission>
    <transmission name="trans_joint_7">
        <type>transmission_interface/SimpleTransmission</type>
        <joint name="joint_7">
            <hardwareInterface>hardware_interface/EffortJointInterface</hardwareInterface>
        </joint>
        <actuator name="joint_7_motor">
            <hardwareInterface>hardware_interface/EffortJointInterface</hardwareInterface>
            <mechanicalReduction>1</mechanicalReduction>
        </actuator>
    </transmission>
    <gazebo>
        <plugin name="gazebo_ros_control">
            <robotNamespace>/</robotNamespace>
        </plugin>
    </gazebo>
</robot>

